Fatal Python error: Segmentation fault

Current thread 0x00007fedaa649600 (most recent call first):
  File "/home/stanislav/anaconda3/envs/env_python_3.7/lib/python3.7/site-packages/slideio/wrappers/py_slideio.py", line 202 in __init__
  File "/home/stanislav/anaconda3/envs/env_python_3.7/lib/python3.7/site-packages/slideio/wrappers/py_slideio.py", line 290 in open_slide
  File "/mnt/d/Projects/slideio/slideio-python-tests/svs/test_svs_driver.py", line 36 in test_file_j2k_metadata
  File "/home/stanislav/anaconda3/envs/env_python_3.7/lib/python3.7/unittest/case.py", line 628 in run
  File "/home/stanislav/anaconda3/envs/env_python_3.7/lib/python3.7/unittest/case.py", line 676 in __call__
  File "/home/stanislav/anaconda3/envs/env_python_3.7/lib/python3.7/site-packages/_pytest/unittest.py", line 333 in runtest
  File "/home/stanislav/anaconda3/envs/env_python_3.7/lib/python3.7/site-packages/_pytest/runner.py", line 169 in pytest_runtest_call
  File "/home/stanislav/anaconda3/envs/env_python_3.7/lib/python3.7/site-packages/pluggy/_callers.py", line 80 in _multicall
  File "/home/stanislav/anaconda3/envs/env_python_3.7/lib/python3.7/site-packages/pluggy/_manager.py", line 112 in _hookexec
  File "/home/stanislav/anaconda3/envs/env_python_3.7/lib/python3.7/site-packages/pluggy/_hooks.py", line 433 in __call__
  File "/home/stanislav/anaconda3/envs/env_python_3.7/lib/python3.7/site-packages/_pytest/runner.py", line 262 in <lambda>
  File "/home/stanislav/anaconda3/envs/env_python_3.7/lib/python3.7/site-packages/_pytest/runner.py", line 341 in from_call
  File "/home/stanislav/anaconda3/envs/env_python_3.7/lib/python3.7/site-packages/_pytest/runner.py", line 262 in call_runtest_hook
  File "/home/stanislav/anaconda3/envs/env_python_3.7/lib/python3.7/site-packages/_pytest/runner.py", line 222 in call_and_report
  File "/home/stanislav/anaconda3/envs/env_python_3.7/lib/python3.7/site-packages/_pytest/runner.py", line 133 in runtestprotocol
  File "/home/stanislav/anaconda3/envs/env_python_3.7/lib/python3.7/site-packages/_pytest/runner.py", line 114 in pytest_runtest_protocol
  File "/home/stanislav/anaconda3/envs/env_python_3.7/lib/python3.7/site-packages/pluggy/_callers.py", line 80 in _multicall
  File "/home/stanislav/anaconda3/envs/env_python_3.7/lib/python3.7/site-packages/pluggy/_manager.py", line 112 in _hookexec
  File "/home/stanislav/anaconda3/envs/env_python_3.7/lib/python3.7/site-packages/pluggy/_hooks.py", line 433 in __call__
  File "/home/stanislav/anaconda3/envs/env_python_3.7/lib/python3.7/site-packages/_pytest/main.py", line 350 in pytest_runtestloop
  File "/home/stanislav/anaconda3/envs/env_python_3.7/lib/python3.7/site-packages/pluggy/_callers.py", line 80 in _multicall
  File "/home/stanislav/anaconda3/envs/env_python_3.7/lib/python3.7/site-packages/pluggy/_manager.py", line 112 in _hookexec
  File "/home/stanislav/anaconda3/envs/env_python_3.7/lib/python3.7/site-packages/pluggy/_hooks.py", line 433 in __call__
  File "/home/stanislav/anaconda3/envs/env_python_3.7/lib/python3.7/site-packages/_pytest/main.py", line 325 in _main
  File "/home/stanislav/anaconda3/envs/env_python_3.7/lib/python3.7/site-packages/_pytest/main.py", line 271 in wrap_session
  File "/home/stanislav/anaconda3/envs/env_python_3.7/lib/python3.7/site-packages/_pytest/main.py", line 318 in pytest_cmdline_main
  File "/home/stanislav/anaconda3/envs/env_python_3.7/lib/python3.7/site-packages/pluggy/_callers.py", line 80 in _multicall
  File "/home/stanislav/anaconda3/envs/env_python_3.7/lib/python3.7/site-packages/pluggy/_manager.py", line 112 in _hookexec
  File "/home/stanislav/anaconda3/envs/env_python_3.7/lib/python3.7/site-packages/pluggy/_hooks.py", line 433 in __call__
  File "/home/stanislav/anaconda3/envs/env_python_3.7/lib/python3.7/site-packages/_pytest/config/__init__.py", line 170 in main
  File "/home/stanislav/anaconda3/envs/env_python_3.7/lib/python3.7/site-packages/_pytest/config/__init__.py", line 192 in console_main
  File "/home/stanislav/anaconda3/envs/env_python_3.7/lib/python3.7/site-packages/pytest/__main__.py", line 5 in <module>
  File "/home/stanislav/anaconda3/envs/env_python_3.7/lib/python3.7/runpy.py", line 85 in _run_code
  File "/home/stanislav/anaconda3/envs/env_python_3.7/lib/python3.7/runpy.py", line 193 in _run_module_as_main
